<?xml version="1.0"?>
<robot xmlns:xacro="http://www.ros.org/wiki/xacro" >

    <xacro:include filename="inertial_macros.xacro"/>

    <material name="white">
        <color rgba="1 1 1 1" />
    </material>

    <material name="orange">
        <color rgba="1 0.3 0.1 1"/>
    </material>

    <material name="blue">
        <color rgba="0.2 0.2 1 1"/>
    </material>

    <material name="black">
        <color rgba="0 0 0 1"/>
    </material>

    <!-- BASE LINK -->

    <link name="base_link">
        <xacro:inertial_box mass="0.01" x="0.01" y="0.01" z="0.01">
            <origin xyz="0 0 0" rpy="0 0 0"/>
        </xacro:inertial_box>
        <!-- <inertial>
            <mass value="0.00001"/>
        </inertial> -->
    </link>


    <!-- CHASSIS LINK -->

    <joint name="chassis_joint" type="fixed">
        <parent link="base_link"/>
        <child link="chassis"/>
        <origin xyz="-0.1 0 0"/>
    </joint>

    <link name="chassis">
        <visual>
            <origin xyz="0.15 0 0.075"/>
            <geometry>
                <box size="0.3 0.3 0.15"/>
            </geometry>
            <material name="white"/>
        </visual>
        <collision>
            <origin xyz="0.15 0 0.075"/>
            <geometry>
                <box size="0.3 0.3 0.15"/>
            </geometry>
        </collision>
        <xacro:inertial_box mass="0.5" x="0.3" y="0.3" z="0.15">
            <origin xyz="0.15 0 0.075" rpy="0 0 0"/>
        </xacro:inertial_box>
    </link>
    
    <!-- LEFT WHEEL LINK -->

    <joint name="left_wheel_joint" type="continuous">
        <parent link="base_link"/>
        <child link="left_wheel"/>
        <origin xyz="0 0.175 0" rpy="-${pi/2} 0 0" />
        <axis xyz="0 0 1"/>
    </joint>

    <link name="left_wheel">
        <visual>
            <geometry>
                <cylinder radius="0.05" length="0.04"/>
            </geometry>
            <material name="blue"/>
        </visual>
        <collision>
            <geometry>
                <cylinder radius="0.05" length="0.04"/>
            </geometry>
        </collision>
        <xacro:inertial_cylinder mass="0.1" length="0.04" radius="0.05">
            <origin xyz="0 0 0" rpy="0 0 0"/>
        </xacro:inertial_cylinder>
    </link>

    <!-- RIGHT WHEEL LINK -->

    <joint name="right_wheel_joint" type="continuous">
        <parent link="base_link"/>
        <child link="right_wheel"/>
        <origin xyz="0 -0.175 0" rpy="${pi/2} 0 0" />
        <axis xyz="0 0 -1"/>
    </joint>

    <link name="right_wheel">
        <visual>
            <geometry>
                <cylinder radius="0.05" length="0.04"/>
            </geometry>
            <material name="blue"/>
        </visual>
        <collision>
            <geometry>
                <cylinder radius="0.05" length="0.04"/>
            </geometry>
        </collision>
        <xacro:inertial_cylinder mass="0.1" length="0.04" radius="0.05">
            <origin xyz="0 0 0" rpy="0 0 0"/>
        </xacro:inertial_cylinder>
    </link>

    <!-- CASTER WHEEL LINK -->

    <joint name="caster_wheel_joint" type="fixed">
        <parent link="chassis"/>
        <child link="caster_wheel"/>
        <origin xyz="0.24 0 0"/>
    </joint>


    <link name="caster_wheel">
        <visual>
            <geometry>
                <sphere radius="0.05"/>
            </geometry>
            <material name="black"/>
        </visual>
        <collision>
            <geometry>
                <sphere radius="0.05"/>
            </geometry>
        </collision>
        <xacro:inertial_sphere mass="0.1" radius="0.05">
            <origin xyz="0 0 0" rpy="0 0 0"/>
        </xacro:inertial_sphere>
    </link>


    <!-- LIDAR -->
    <joint name="lidar_joint" type="fixed">
        <parent link="base_link"/>
        <child link="lidar_link"/>
        <origin xyz="0.0 0.0 0.18"/>    
    </joint>
   <link name="lidar_link">
        <visual>
            <geometry>
                <box size="0.05 0.05 0.05"/>
            </geometry>
        </visual>
        <collision>
            <geometry>
                <box size="0.05 0.05 0.05"/>
            </geometry>
        </collision>
        <xacro:inertial_box mass="0.1" x="0.05" y="0.05" z="0.05">
            <origin xyz="0 0 0" rpy="0 0 0"/>
        </xacro:inertial_box>
   </link>

    <gazebo reference="lidar_joint">
        <preserveFixedJoint>true</preserveFixedJoint>
    </gazebo>

    <gazebo reference="chassis_joint">
        <preserveFixedJoint>true</preserveFixedJoint>
    </gazebo> 
    <gazebo reference="caster_wheel_joint">
        <preserveFixedJoint>true</preserveFixedJoint>
    </gazebo> 
    

    <gazebo reference="lidar_link">
        <sensor name='gpu_lidar' type='gpu_lidar'>"
          <pose relative_to='lidar_link'>0 0 0 0 0 0</pose>
          <topic>roboto/scan</topic>
          <gz_frame_id>roboto/lidar_link</gz_frame_id>
          <update_rate>5</update_rate>
          <ray>
              <scan>
                  <horizontal>
                      <samples>500</samples>
                      <resolution>1</resolution>
                      <min_angle>-3.14</min_angle>
                      <max_angle>3.14</max_angle>
                  </horizontal>
                  <vertical>
                      <samples>1</samples>
                      <resolution>0.01</resolution>
                      <min_angle>0</min_angle>
                      <max_angle>0</max_angle>
                  </vertical>
              </scan>
              <range>
                  <min>0.08</min>
                  <max>10.0</max>
                  <resolution>0.01</resolution>
              </range>
          </ray>
          <always_on>1</always_on>
          <visualize>true</visualize>
      </sensor>
    </gazebo>
</robot>