<?xml version="1.0"?>
<robot xmlns:xacro="http://www.ros.org/wiki/xacro" >

    <xacro:include filename="inertial_macros.xacro"/>

    <xacro:include filename="$(find roboto_diffbot)/description/robot/materials.xacro" />



    <link name="base_link">
    <inertial>
        <origin xyz="-0.0022769860063732495 -0.0006106463755604264 0.0295548678674386" rpy="0 0 0"/>
        <mass value="0.5933300696386302"/>
        <inertia ixx="0.001482" iyy="0.002089" izz="0.002883" ixy="6.5e-05" iyz="1.2e-05" ixz="-0.0001"/>
    </inertial>
    <visual>
        <origin xyz="0 0 0" rpy="0 0 0"/>
        <geometry>
        <mesh filename="file://$(find roboto_diffbot)/description/robot/meshes/base_link.stl" scale="0.001 0.001 0.001"/>
        </geometry>
        <material name="silver"/>
    </visual>
    <collision>
        <origin xyz="0 0 0" rpy="0 0 0"/>
        <geometry>
        <mesh filename="file://$(find roboto_diffbot)/description/robot/meshes/base_link.stl" scale="0.001 0.001 0.001"/>
        </geometry>
    </collision>
    </link>

    <joint name="base_footprint_joint" type="fixed">
        <parent link="base_link"/>
        <child link="base_footprint"/>
        <origin xyz="0.0 0.0 0.0" rpy="0.0 0.0 0.0"/>
    </joint>

    <link name="base_footprint">
        
    </link>

    <link name="left_wheel">
    <inertial>
        <origin xyz="-4.928047540112002e-07 0.00649999998366961 1.4028976041274843e-07" rpy="0 0 0"/>
        <mass value="0.06534512719466766"/>
        <inertia ixx="2.7e-05" iyy="5.2e-05" izz="2.7e-05" ixy="0.0" iyz="0.0" ixz="0.0"/>
    </inertial>
    <visual>
        <origin xyz="0.014004 -0.078 -0.021997" rpy="0 0 0"/>
        <geometry>
        <mesh filename="file://$(find roboto_diffbot)/description/robot/meshes/left_wheel_1.stl" scale="0.001 0.001 0.001"/>
        </geometry>
        <material name="silver"/>
    </visual>
    <collision>
        <origin xyz="0.014004 -0.078 -0.021997" rpy="0 0 0"/>
        <geometry>
        <mesh filename="file://$(find roboto_diffbot)/description/robot/meshes/left_wheel_1.stl" scale="0.001 0.001 0.001"/>
        </geometry>
    </collision>
    </link>

    <link name="right_wheel">
    <inertial>
        <origin xyz="-4.928279983152511e-07 -0.006499999983669735 1.4028975616267592e-07" rpy="0 0 0"/>
        <mass value="0.06534512719466772"/>
        <inertia ixx="2.7e-05" iyy="5.2e-05" izz="2.7e-05" ixy="0.0" iyz="0.0" ixz="0.0"/>
    </inertial>
    <visual>
        <origin xyz="0.014004 0.078 -0.021997" rpy="0 0 0"/>
        <geometry>
        <mesh filename="file://$(find roboto_diffbot)/description/robot/meshes/right_wheel_1.stl" 
            scale="0.001 0.001 0.001"/>
        </geometry>
        <material name="silver"/>
    </visual>
    <collision>
        <origin xyz="0.014004 0.078 -0.021997" rpy="0 0 0"/>
        <geometry>
        <mesh filename="file://$(find roboto_diffbot)/description/robot/meshes/right_wheel_1.stl" 
            scale="0.001 0.001 0.001"/>
        </geometry>
    </collision>
    </link>

    <joint name="right_wheel_joint" type="continuous">
        <origin xyz="-0.014004 -0.078 0.021997" rpy="0 0 0"/>
        <parent link="base_link"/>
        <child link="right_wheel"/>
        <axis xyz="-0.0 1.0 -0.0"/>
    </joint>

    <link name="lidar_link">
    <inertial>
        <origin xyz="1.0280064668785616e-05 1.1690792628638037e-07 0.012400389023013991" rpy="0 0 0"/>
        <mass value="0.005290200757156612"/>
        <inertia ixx="1e-06" iyy="1e-06" izz="2e-06" ixy="-0.0" iyz="-0.0" ixz="-0.0"/>
    </inertial>
    <visual>
        <origin xyz="-0.067726 -0.0 -0.084534" rpy="0 0 0"/>
        <geometry>
        <mesh filename="file://$(find roboto_diffbot)/description/robot/meshes/lidar_link_1.stl" scale="0.001 0.001 0.001"/>
        </geometry>
        <material name="silver"/>
    </visual>
    <collision>
        <origin xyz="-0.067726 -0.0 -0.084534" rpy="0 0 0"/>
        <geometry>
        <mesh filename="file://$(find roboto_diffbot)/description/robot/meshes/lidar_link_1.stl" scale="0.001 0.001 0.001"/>
        </geometry>
    </collision>
    </link>

    <joint name="left_wheel_joint" type="continuous">
    <origin xyz="-0.014004 0.078 0.021997" rpy="0 0 0"/>
    <parent link="base_link"/>
    <child link="left_wheel"/>
    <axis xyz="0.0 1.0 0.0"/>
    </joint>


    <joint name="lidar_joint" type="fixed">
    <origin xyz="0.067726 0.0 0.084534" rpy="0 0 ${pi}"/>
    <parent link="base_link"/>
    <child link="lidar_link"/>
    </joint>

    <joint name="caster_wheel_joint" type="fixed">
        <parent link="base_link"/>
        <child link="caster_wheel"/>
        <origin xyz="0.064 0 -0.012"/>
    </joint>

    <link name="caster_wheel">
        <visual>
            <geometry>
                <sphere radius="0.0063"/>
            </geometry>
            <material name="black"/>
        </visual>
        <collision>
            <geometry>
                <sphere radius="0.0063"/>
            </geometry>
        </collision>
        <xacro:inertial_sphere mass="0.02" radius="0.0063">
            <origin xyz="0 0 0" rpy="0 0 0"/>
        </xacro:inertial_sphere>
    </link>

</robot>