<?xml version="1.0" ?>
<sdf version="1.6">
  <model name="differential_drive_robot">
    <static>false</static>

    <!-- Base Link -->
    <link name="base_link">

    </link>

    <!-- Chassis Link -->
    <link name="chassis">
      <pose>-0.1 0 0 0 0 0</pose>
      <inertial>
        <pose>0.15 0 0.075 0 0 0</pose>
        <mass>0.59999999999999998</mass>
        <inertia>
          <ixx>0.0052562499999999988</ixx>
          <ixy>0</ixy>
          <ixz>0.00056250000000000007</ixz>
          <iyy>0.0059312499999999964</iyy>
          <iyz>0</iyz>
          <izz>0.0082749999999999976</izz>
        </inertia>
      </inertial>
      <collision name="collision">
        <pose>0.15 0 0.075 0 0 0</pose>
        <geometry>
          <box>
            <size>0.3 0.3 0.15</size>
          </box>
        </geometry>
      </collision>
      <visual name="visual">
        <pose>0.15 0 0.075 0 0 0</pose>
        <geometry>
          <box>
            <size>0.3 0.3 0.15</size>
          </box>
        </geometry>
        <material>
          <diffuse>1 1 1 1</diffuse>
          <ambient>1 1 1 1</ambient>
        </material>
      </visual>
    </link>
    <joint name="chassis_joint" type="fixed">
      <parent>base_link</parent>
      <child>chassis</child>
    </joint>

    <!-- Left Wheel -->
    <link name="left_wheel">
      <pose>0 0.175 0 -1.5708 0 0</pose>
      <inertial>
        <mass>1.0</mass>
        <inertia>
          <ixx>0.01</ixx>
          <iyy>0.01</iyy>
          <izz>0.01</izz>
        </inertia>
      </inertial>
      <collision name="collision">
        <geometry>
          <cylinder>
            <radius>0.05</radius>
            <length>0.04</length>
          </cylinder>
        </geometry>
      </collision>
      <visual name="visual">
        <geometry>
          <cylinder>
            <radius>0.05</radius>
            <length>0.04</length>
          </cylinder>
        </geometry>
        <material>
          <diffuse>0.25 0.25 1 1</diffuse>
          <ambient>0.25 0.25 1 1</ambient>
        </material>
      </visual>
    </link>
    <joint name="left_wheel_joint" type="revolute">
      <parent>base_link</parent>
      <child>left_wheel</child>
      <axis>
        <xyz>0 0 1</xyz>
        <limit>
          <lower>-10000000000000000</lower>
          <upper>10000000000000000</upper>
        </limit>
      </axis>
    </joint>

    <!-- Right Wheel -->
    <link name="right_wheel">
      <pose>0 -0.175 0 1.5708 0 0</pose>
      <inertial>
        <pose>0 0 0 0 0 0</pose>
        <mass>0.10000000000000001</mass>
        <inertia>
          <ixx>7.5833333333333352e-05</ixx>
          <ixy>0</ixy>
          <ixz>0</ixz>
          <iyy>7.5833333333333352e-05</iyy>
          <iyz>0</iyz>
          <izz>0.000125</izz>
        </inertia>
      </inertial>
      <collision name="collision">
        <geometry>
          <cylinder>
            <radius>0.05</radius>
            <length>0.04</length>
          </cylinder>
        </geometry>
      </collision>
      <visual name="visual">
        <geometry>
          <cylinder>
            <radius>0.05</radius>
            <length>0.04</length>
          </cylinder>
        </geometry>
        <material>
          <diffuse>0.25 0.25 1 1</diffuse>
          <ambient>0.25 0.25 1 1</ambient>
        </material>
      </visual>
    </link>
    <joint name="right_wheel_joint" type="revolute">
      <parent>base_link</parent>
      <child>right_wheel</child>
      <axis>
        <xyz>0 0 -1</xyz>
        <limit>
          <lower>-10000000000000000</lower>
          <upper>10000000000000000</upper>
        </limit>
      </axis>
    </joint>

    <!-- Caster Wheel -->
    <link name="caster_wheel">
      <pose>0.14 0 0 0 0 0</pose>
      <inertial>
        <mass>0.5</mass>
        <inertia>
          <ixx>0.005</ixx>
          <iyy>0.005</iyy>
          <izz>0.005</izz>
        </inertia>
      </inertial>
      <collision name="collision">
        <geometry>
          <sphere>
            <radius>0.05</radius>
          </sphere>
        </geometry>
      </collision>
      <surface>
        <friction>
          <ode>
            <mu>0.005</mu>
            <mu2>0.005</mu2>
          </ode>
        </friction>
      </surface>
      <visual name="visual">
        <geometry>
          <sphere>
            <radius>0.05</radius>
          </sphere>
        </geometry>
        <material>
          <diffuse>0.25 0.25 1 1</diffuse>
          <ambient>0.25 0.25 1 1</ambient>
        </material>
      </visual>
    </link>
    <joint name="caster_wheel_joint" type="fixed">
      <parent>chassis</parent>
      <child>caster_wheel</child>
    </joint>

    <link name="lidar_link">
      <pose>0 0 0.18 0 0 0</pose>
      <inertial>
        <mass>0.1</mass>
        <inertia>
          <ixx>0.000166667</ixx>
          <iyy>0.000166667</iyy>
          <izz>0.000166667</izz>
        </inertia>
      </inertial>
      <collision name="collision">
        <geometry>
          <box>
            <size>0.05 0.05 0.05</size>
          </box>
        </geometry>
      </collision>
      <visual name="visual">
        <geometry>
          <box>
            <size>0.05 0.05 0.05</size>
          </box>
        </geometry>
      </visual>
<sensor name='gpu_lidar' type='gpu_lidar'>"
    <pose relative_to='lidar_link'>0 0 0 0 0 0</pose>
    <topic>scan</topic>
    <gz_frame_id>roboto/lidar_link</gz_frame_id>
    <update_rate>5</update_rate>
    <ray>
        <scan>
            <horizontal>
                <samples>500</samples>
                <resolution>1</resolution>
                <min_angle>-3.14</min_angle>
                <max_angle>3.14</max_angle>
            </horizontal>
            <vertical>
                <samples>1</samples>
                <resolution>0.01</resolution>
                <min_angle>0</min_angle>
                <max_angle>0</max_angle>
            </vertical>
        </scan>
        <range>
            <min>0.08</min>
            <max>10.0</max>
            <resolution>0.01</resolution>
        </range>
    </ray>
    <always_on>1</always_on>
    <visualize>true</visualize>
</sensor>
    </link>

    <joint name='lidar_joint' type='fixed'>
      <parent>base_link</parent>
      <child>lidar_link</child>
    </joint>

    <!-- Differential Drive Plugin -->
  <plugin filename="gz-sim-diff-drive-system" name="gz::sim::systems::DiffDrive">
    <left_joint>left_wheel_joint</left_joint>
    <right_joint>right_wheel_joint</right_joint>
    <wheel_separation>0.35</wheel_separation>
    <wheel_radius>0.05</wheel_radius>
    <max_acceleration>0.3</max_acceleration>
    <min_acceleration>-0.3</min_acceleration>
  </plugin>

  </model>
</sdf>
